Workbook

Sheet README
A1: NammaBasket Store Location Prototype
A2: Where should the next store open? Multi-criteria + unit-economics model (fictional chain, Bengaluru)
A4: Purpose | B4: Compare 8 shortlisted neighbourhoods and recommend which to open within a capex budget, with reasons and trade-offs.
A5: Journey | B5: Inputs (Candidates, Existing_Stores, Assumptions, Weights) -> Model (demand, cannibalisation, P&L) -> Cashflows (9-yr NPV) -> Scoring (0-100) -> Recommendation.
A6: Decision logic | B6: 1) Financial gate: payback <= max payback AND 9-yr NPV > 0. 2) Rank gate-passers by weighted score. 3) Pick greedily within capex budget, skipping sites closer than the min pair distance to an already-picked site.
A7: Colour legend | B7: Blue text = input you can change. Black = formula. Green = link to another sheet. Yellow fill = key assumption.
A8: How to use | B8: Change any blue cell (e.g. a weight on Weights, rent on Candidates, budget on Assumptions). Everything recalculates, including the recommendation.
A9: Example edit | B9: Set Weights!C6 (Competition) to 20% and Weights!C4 (Demand) to 10%: Sarjapur Road overtakes Whitefield for slot 2.
A10: Data | B10: Locality data is SYNTHETIC but calibrated to public benchmarks (see Assumptions column D). Existing-store sales are synthetic "actuals" used to calibrate the demand model.
A11: Units | B11: Sales, EBITDA, capex, NPV in Rs crore (1 Cr = 10 million). Rent in Rs per sq ft per month. Income in Rs per household per month.

Sheet Recommendation
A1: Recommendation: where to open next
A2: Gate -> rank by weighted score -> pick within budget, keeping new stores apart. Updates live when any blue input changes.
A3: RECOMMENDED SITES | C3: =IFERROR(INDEX($B$7:$B$14,MATCH(1,$P$7:$P$14,0)),"None")&IFERROR(" + "&INDEX($B$7:$B$14,MATCH(2,$P$7:$P$14,0)),"")&IFERROR(" + "&INDEX($B$7:$B$14,MATCH(3,$P$7:$P$14,0)),"") -> Kanakapura Road + Whitefield
A4: Capex committed / budget (Rs Cr) | C4: =SUMPRODUCT(L7:L14,H7:H14) -> 7.26 | D4: =Assumptions!$B$34/10^7 -> 8 | E4: Combined 9-yr NPV (Rs Cr) | G4: =SUMPRODUCT(L7:L14,F7:F14) -> 8.6544118
A6: Rank | B6: Location | C6: Weighted score | D6: Passes gate | E6: Gross sales (Rs Cr) | F6: 9-yr NPV (Rs Cr) | G6: Payback (yrs) | H6: Capex (Rs Cr) | I6: Cannibalisation | J6: Min km to earlier pick | K6: Capex before this site | L6: Selected (1/0) | M6: Verdict | N6: Strongest | O6: Weakest | P6: Pick #
A7: 1 | B7: =INDEX(Scoring!$A$5:$A$12,MATCH($A7,Scoring!$S$5:$S$12,0)) -> Kanakapura Road | C7: =INDEX(Scoring!$P$5:$P$12,MATCH($A7,Scoring!$S$5:$S$12,0)) -> 87.226836 | D7: =INDEX(Scoring!$Q$5:$Q$12,MATCH($A7,Scoring!$S$5:$S$12,0)) -> Yes | E7: =INDEX(Model!$L$5:$L$12,MATCH($A7,Scoring!$S$5:$S$12,0)) -> 29.474373 | F7: =INDEX(Model!$Y$5:$Y$12,MATCH($A7,Scoring!$S$5:$S$12,0)) -> 5.9694209 | G7: =INDEX(Model!$X$5:$X$12,MATCH($A7,Scoring!$S$5:$S$12,0)) -> 1.9843867 | H7: =INDEX(Model!$W$5:$W$12,MATCH($A7,Scoring!$S$5:$S$12,0)) -> 3.39 | I7: =INDEX(Model!$P$5:$P$12,MATCH($A7,Scoring!$S$5:$S$12,0)) -> 0.11186905 | J7: 999 | K7: =0 -> 0 | L7: =IF(AND(D7="Yes",K7+H7<=Assumptions!$B$34/10^7,J7>=Assumptions!$B$36),1,0) -> 1 | M7: =IF(L7=1,"OPEN",IF(D7="No",IF(INDEX(Model!$V$5:$V$12,MATCH($A7,Scoring!$S$5:$S$12,0))<=0,"Reject: negative incremental EBITDA","Reject: fails payback/NPV gate"),IF(J7<Assumptions!$B$36,"Hold: too close to a new pick","Reserve: next in line if budget grows"))) -> OPEN | N7: =INDEX(Scoring!$T$5:$T$12,MATCH($A7,Scoring!$S$5:$S$12,0)) -> Profitability score | O7: =INDEX(Scoring!$U$5:$U$12,MATCH($A7,Scoring!$S$5:$S$12,0)) -> Cannibalisation score | P7: =IF(L7=1,SUM($L$7:L7),0) -> 1
A8: 2 | B8: =INDEX(Scoring!$A$5:$A$12,MATCH($A8,Scoring!$S$5:$S$12,0)) -> Whitefield | C8: =INDEX(Scoring!$P$5:$P$12,MATCH($A8,Scoring!$S$5:$S$12,0)) -> 73.360426 | D8: =INDEX(Scoring!$Q$5:$Q$12,MATCH($A8,Scoring!$S$5:$S$12,0)) -> Yes | E8: =INDEX(Model!$L$5:$L$12,MATCH($A8,Scoring!$S$5:$S$12,0)) -> 30.600845 | F8: =INDEX(Model!$Y$5:$Y$12,MATCH($A8,Scoring!$S$5:$S$12,0)) -> 2.6849909 | G8: =INDEX(Model!$X$5:$X$12,MATCH($A8,Scoring!$S$5:$S$12,0)) -> 2.6577203 | H8: =INDEX(Model!$W$5:$W$12,MATCH($A8,Scoring!$S$5:$S$12,0)) -> 3.87 | I8: =INDEX(Model!$P$5:$P$12,MATCH($A8,Scoring!$S$5:$S$12,0)) -> 0 | J8: =MIN(IF($L7=1,INDEX(Distances!$B$16:$I$23,MATCH($B8,Distances!$A$16:$A$23,0),MATCH($B7,Distances!$A$16:$A$23,0)),999)) -> 22.226211 | K8: =SUMPRODUCT($L$7:$L7,$H$7:$H7) -> 3.39 | L8: =IF(AND(D8="Yes",K8+H8<=Assumptions!$B$34/10^7,J8>=Assumptions!$B$36),1,0) -> 1 | M8: =IF(L8=1,"OPEN",IF(D8="No",IF(INDEX(Model!$V$5:$V$12,MATCH($A8,Scoring!$S$5:$S$12,0))<=0,"Reject: negative incremental EBITDA","Reject: fails payback/NPV gate"),IF(J8<Assumptions!$B$36,"Hold: too close to a new pick","Reserve: next in line if budget grows"))) -> OPEN | N8: =INDEX(Scoring!$T$5:$T$12,MATCH($A8,Scoring!$S$5:$S$12,0)) -> Demand score | O8: =INDEX(Scoring!$U$5:$U$12,MATCH($A8,Scoring!$S$5:$S$12,0)) -> Competition score | P8: =IF(L8=1,SUM($L$7:L8),0) -> 2
A9: 3 | B9: =INDEX(Scoring!$A$5:$A$12,MATCH($A9,Scoring!$S$5:$S$12,0)) -> Sarjapur Road | C9: =INDEX(Scoring!$P$5:$P$12,MATCH($A9,Scoring!$S$5:$S$12,0)) -> 66.851629 | D9: =INDEX(Scoring!$Q$5:$Q$12,MATCH($A9,Scoring!$S$5:$S$12,0)) -> Yes | E9: =INDEX(Model!$L$5:$L$12,MATCH($A9,Scoring!$S$5:$S$12,0)) -> 27.210956 | F9: =INDEX(Model!$Y$5:$Y$12,MATCH($A9,Scoring!$S$5:$S$12,0)) -> 3.0925247 | G9: =INDEX(Model!$X$5:$X$12,MATCH($A9,Scoring!$S$5:$S$12,0)) -> 3.369028 | H9: =INDEX(Model!$W$5:$W$12,MATCH($A9,Scoring!$S$5:$S$12,0)) -> 3.57 | I9: =INDEX(Model!$P$5:$P$12,MATCH($A9,Scoring!$S$5:$S$12,0)) -> 0.10430086 | J9: =MIN(IF($L7=1,INDEX(Distances!$B$16:$I$23,MATCH($B9,Distances!$A$16:$A$23,0),MATCH($B7,Distances!$A$16:$A$23,0)),999),IF($L8=1,INDEX(Distances!$B$16:$I$23,MATCH($B9,Distances!$A$16:$A$23,0),MATCH($B8,Distances!$A$16:$A$23,0)),999)) -> 8.905627 | K9: =SUMPRODUCT($L$7:$L8,$H$7:$H8) -> 7.26 | L9: =IF(AND(D9="Yes",K9+H9<=Assumptions!$B$34/10^7,J9>=Assumptions!$B$36),1,0) -> 0 | M9: =IF(L9=1,"OPEN",IF(D9="No",IF(INDEX(Model!$V$5:$V$12,MATCH($A9,Scoring!$S$5:$S$12,0))<=0,"Reject: negative incremental EBITDA","Reject: fails payback/NPV gate"),IF(J9<Assumptions!$B$36,"Hold: too close to a new pick","Reserve: next in line if budget grows"))) -> Reserve: next in line if budget grows | N9: =INDEX(Scoring!$T$5:$T$12,MATCH($A9,Scoring!$S$5:$S$12,0)) -> Growth score | O9: =INDEX(Scoring!$U$5:$U$12,MATCH($A9,Scoring!$S$5:$S$12,0)) -> Accessibility score | P9: =IF(L9=1,SUM($L$7:L9),0) -> 0
A10: 4 | B10: =INDEX(Scoring!$A$5:$A$12,MATCH($A10,Scoring!$S$5:$S$12,0)) -> Electronic City | C10: =INDEX(Scoring!$P$5:$P$12,MATCH($A10,Scoring!$S$5:$S$12,0)) -> 61.951873 | D10: =INDEX(Scoring!$Q$5:$Q$12,MATCH($A10,Scoring!$S$5:$S$12,0)) -> Yes | E10: =INDEX(Model!$L$5:$L$12,MATCH($A10,Scoring!$S$5:$S$12,0)) -> 23.050564 | F10: =INDEX(Model!$Y$5:$Y$12,MATCH($A10,Scoring!$S$5:$S$12,0)) -> 1.2626707 | G10: =INDEX(Model!$X$5:$X$12,MATCH($A10,Scoring!$S$5:$S$12,0)) -> 3.4177249 | H10: =INDEX(Model!$W$5:$W$12,MATCH($A10,Scoring!$S$5:$S$12,0)) -> 3.45 | I10: =INDEX(Model!$P$5:$P$12,MATCH($A10,Scoring!$S$5:$S$12,0)) -> 0.02132453 | J10: =MIN(IF($L7=1,INDEX(Distances!$B$16:$I$23,MATCH($B10,Distances!$A$16:$A$23,0),MATCH($B7,Distances!$A$16:$A$23,0)),999),IF($L8=1,INDEX(Distances!$B$16:$I$23,MATCH($B10,Distances!$A$16:$A$23,0),MATCH($B8,Distances!$A$16:$A$23,0)),999),IF($L9=1,INDEX(Distances!$B$16:$I$23,MATCH($B10,Distances!$A$16:$A$23,0),MATCH($B9,Distances!$A$16:$A$23,0)),999)) -> 11.354838 | K10: =SUMPRODUCT($L$7:$L9,$H$7:$H9) -> 7.26 | L10: =IF(AND(D10="Yes",K10+H10<=Assumptions!$B$34/10^7,J10>=Assumptions!$B$36),1,0) -> 0 | M10: =IF(L10=1,"OPEN",IF(D10="No",IF(INDEX(Model!$V$5:$V$12,MATCH($A10,Scoring!$S$5:$S$12,0))<=0,"Reject: negative incremental EBITDA","Reject: fails payback/NPV gate"),IF(J10<Assumptions!$B$36,"Hold: too close to a new pick","Reserve: next in line if budget grows"))) -> Reserve: next in line if budget grows | N10: =INDEX(Scoring!$T$5:$T$12,MATCH($A10,Scoring!$S$5:$S$12,0)) -> Cannibalisation score | O10: =INDEX(Scoring!$U$5:$U$12,MATCH($A10,Scoring!$S$5:$S$12,0)) -> Demand score | P10: =IF(L10=1,SUM($L$7:L10),0) -> 0
A11: 5 | B11: =INDEX(Scoring!$A$5:$A$12,MATCH($A11,Scoring!$S$5:$S$12,0)) -> Yelahanka | C11: =INDEX(Scoring!$P$5:$P$12,MATCH($A11,Scoring!$S$5:$S$12,0)) -> 52.021989 | D11: =INDEX(Scoring!$Q$5:$Q$12,MATCH($A11,Scoring!$S$5:$S$12,0)) -> No | E11: =INDEX(Model!$L$5:$L$12,MATCH($A11,Scoring!$S$5:$S$12,0)) -> 19.829423 | F11: =INDEX(Model!$Y$5:$Y$12,MATCH($A11,Scoring!$S$5:$S$12,0)) -> -1.2598126 | G11: =INDEX(Model!$X$5:$X$12,MATCH($A11,Scoring!$S$5:$S$12,0)) -> 5.4053403 | H11: =INDEX(Model!$W$5:$W$12,MATCH($A11,Scoring!$S$5:$S$12,0)) -> 3.42 | I11: =INDEX(Model!$P$5:$P$12,MATCH($A11,Scoring!$S$5:$S$12,0)) -> 0 | J11: =MIN(IF($L7=1,INDEX(Distances!$B$16:$I$23,MATCH($B11,Distances!$A$16:$A$23,0),MATCH($B7,Distances!$A$16:$A$23,0)),999),IF($L8=1,INDEX(Distances!$B$16:$I$23,MATCH($B11,Distances!$A$16:$A$23,0),MATCH($B8,Distances!$A$16:$A$23,0)),999),IF($L9=1,INDEX(Distances!$B$16:$I$23,MATCH($B11,Distances!$A$16:$A$23,0),MATCH($B9,Distances!$A$16:$A$23,0)),999),IF($L10=1,INDEX(Distances!$B$16:$I$23,MATCH($B11,Distances!$A$16:$A$23,0),MATCH($B10,Distances!$A$16:$A$23,0)),999)) -> 22.115405 | K11: =SUMPRODUCT($L$7:$L10,$H$7:$H10) -> 7.26 | L11: =IF(AND(D11="Yes",K11+H11<=Assumptions!$B$34/10^7,J11>=Assumptions!$B$36),1,0) -> 0 | M11: =IF(L11=1,"OPEN",IF(D11="No",IF(INDEX(Model!$V$5:$V$12,MATCH($A11,Scoring!$S$5:$S$12,0))<=0,"Reject: negative incremental EBITDA","Reject: fails payback/NPV gate"),IF(J11<Assumptions!$B$36,"Hold: too close to a new pick","Reserve: next in line if budget grows"))) -> Reject: fails payback/NPV gate | N11: =INDEX(Scoring!$T$5:$T$12,MATCH($A11,Scoring!$S$5:$S$12,0)) -> Competition score | O11: =INDEX(Scoring!$U$5:$U$12,MATCH($A11,Scoring!$S$5:$S$12,0)) -> Demand score | P11: =IF(L11=1,SUM($L$7:L11),0) -> 0
A12: 6 | B12: =INDEX(Scoring!$A$5:$A$12,MATCH($A12,Scoring!$S$5:$S$12,0)) -> Hebbal | C12: =INDEX(Scoring!$P$5:$P$12,MATCH($A12,Scoring!$S$5:$S$12,0)) -> 45.885679 | D12: =INDEX(Scoring!$Q$5:$Q$12,MATCH($A12,Scoring!$S$5:$S$12,0)) -> No | E12: =INDEX(Model!$L$5:$L$12,MATCH($A12,Scoring!$S$5:$S$12,0)) -> 26.936033 | F12: =INDEX(Model!$Y$5:$Y$12,MATCH($A12,Scoring!$S$5:$S$12,0)) -> -2.8516367 | G12: =INDEX(Model!$X$5:$X$12,MATCH($A12,Scoring!$S$5:$S$12,0)) -> 7.1096185 | H12: =INDEX(Model!$W$5:$W$12,MATCH($A12,Scoring!$S$5:$S$12,0)) -> 3.72 | I12: =INDEX(Model!$P$5:$P$12,MATCH($A12,Scoring!$S$5:$S$12,0)) -> 0.15001524 | J12: =MIN(IF($L7=1,INDEX(Distances!$B$16:$I$23,MATCH($B12,Distances!$A$16:$A$23,0),MATCH($B7,Distances!$A$16:$A$23,0)),999),IF($L8=1,INDEX(Distances!$B$16:$I$23,MATCH($B12,Distances!$A$16:$A$23,0),MATCH($B8,Distances!$A$16:$A$23,0)),999),IF($L9=1,INDEX(Distances!$B$16:$I$23,MATCH($B12,Distances!$A$16:$A$23,0),MATCH($B9,Distances!$A$16:$A$23,0)),999),IF($L10=1,INDEX(Distances!$B$16:$I$23,MATCH($B12,Distances!$A$16:$A$23,0),MATCH($B10,Distances!$A$16:$A$23,0)),999),IF($L11=1,INDEX(Distances!$B$16:$I$23,MATCH($B12,Distances!$A$16:$A$23,0),MATCH($B11,Distances!$A$16:$A$23,0)),999)) -> 17.080011 | K12: =SUMPRODUCT($L$7:$L11,$H$7:$H11) -> 7.26 | L12: =IF(AND(D12="Yes",K12+H12<=Assumptions!$B$34/10^7,J12>=Assumptions!$B$36),1,0) -> 0 | M12: =IF(L12=1,"OPEN",IF(D12="No",IF(INDEX(Model!$V$5:$V$12,MATCH($A12,Scoring!$S$5:$S$12,0))<=0,"Reject: negative incremental EBITDA","Reject: fails payback/NPV gate"),IF(J12<Assumptions!$B$36,"Hold: too close to a new pick","Reserve: next in line if budget grows"))) -> Reject: fails payback/NPV gate | N12: =INDEX(Scoring!$T$5:$T$12,MATCH($A12,Scoring!$S$5:$S$12,0)) -> Accessibility score | O12: =INDEX(Scoring!$U$5:$U$12,MATCH($A12,Scoring!$S$5:$S$12,0)) -> Growth score | P12: =IF(L12=1,SUM($L$7:L12),0) -> 0
A13: 7 | B13: =INDEX(Scoring!$A$5:$A$12,MATCH($A13,Scoring!$S$5:$S$12,0)) -> Bellandur | C13: =INDEX(Scoring!$P$5:$P$12,MATCH($A13,Scoring!$S$5:$S$12,0)) -> 30.499175 | D13: =INDEX(Scoring!$Q$5:$Q$12,MATCH($A13,Scoring!$S$5:$S$12,0)) -> No | E13: =INDEX(Model!$L$5:$L$12,MATCH($A13,Scoring!$S$5:$S$12,0)) -> 26.906683 | F13: =INDEX(Model!$Y$5:$Y$12,MATCH($A13,Scoring!$S$5:$S$12,0)) -> -4.1151219 | G13: =INDEX(Model!$X$5:$X$12,MATCH($A13,Scoring!$S$5:$S$12,0)) -> 18.991827 | H13: =INDEX(Model!$W$5:$W$12,MATCH($A13,Scoring!$S$5:$S$12,0)) -> 3.78 | I13: =INDEX(Model!$P$5:$P$12,MATCH($A13,Scoring!$S$5:$S$12,0)) -> 0.19652094 | J13: =MIN(IF($L7=1,INDEX(Distances!$B$16:$I$23,MATCH($B13,Distances!$A$16:$A$23,0),MATCH($B7,Distances!$A$16:$A$23,0)),999),IF($L8=1,INDEX(Distances!$B$16:$I$23,MATCH($B13,Distances!$A$16:$A$23,0),MATCH($B8,Distances!$A$16:$A$23,0)),999),IF($L9=1,INDEX(Distances!$B$16:$I$23,MATCH($B13,Distances!$A$16:$A$23,0),MATCH($B9,Distances!$A$16:$A$23,0)),999),IF($L10=1,INDEX(Distances!$B$16:$I$23,MATCH($B13,Distances!$A$16:$A$23,0),MATCH($B10,Distances!$A$16:$A$23,0)),999),IF($L11=1,INDEX(Distances!$B$16:$I$23,MATCH($B13,Distances!$A$16:$A$23,0),MATCH($B11,Distances!$A$16:$A$23,0)),999),IF($L12=1,INDEX(Distances!$B$16:$I$23,MATCH($B13,Distances!$A$16:$A$23,0),MATCH($B12,Distances!$A$16:$A$23,0)),999)) -> 9.3638017 | K13: =SUMPRODUCT($L$7:$L12,$H$7:$H12) -> 7.26 | L13: =IF(AND(D13="Yes",K13+H13<=Assumptions!$B$34/10^7,J13>=Assumptions!$B$36),1,0) -> 0 | M13: =IF(L13=1,"OPEN",IF(D13="No",IF(INDEX(Model!$V$5:$V$12,MATCH($A13,Scoring!$S$5:$S$12,0))<=0,"Reject: negative incremental EBITDA","Reject: fails payback/NPV gate"),IF(J13<Assumptions!$B$36,"Hold: too close to a new pick","Reserve: next in line if budget grows"))) -> Reject: fails payback/NPV gate | N13: =INDEX(Scoring!$T$5:$T$12,MATCH($A13,Scoring!$S$5:$S$12,0)) -> Demand score | O13: =INDEX(Scoring!$U$5:$U$12,MATCH($A13,Scoring!$S$5:$S$12,0)) -> Accessibility score | P13: =IF(L13=1,SUM($L$7:L13),0) -> 0
A14: 8 | B14: =INDEX(Scoring!$A$5:$A$12,MATCH($A14,Scoring!$S$5:$S$12,0)) -> Marathahalli | C14: =INDEX(Scoring!$P$5:$P$12,MATCH($A14,Scoring!$S$5:$S$12,0)) -> 20.973983 | D14: =INDEX(Scoring!$Q$5:$Q$12,MATCH($A14,Scoring!$S$5:$S$12,0)) -> No | E14: =INDEX(Model!$L$5:$L$12,MATCH($A14,Scoring!$S$5:$S$12,0)) -> 22.228569 | F14: =INDEX(Model!$Y$5:$Y$12,MATCH($A14,Scoring!$S$5:$S$12,0)) -> -7.1823773 | G14: =INDEX(Model!$X$5:$X$12,MATCH($A14,Scoring!$S$5:$S$12,0)) -> 99 | H14: =INDEX(Model!$W$5:$W$12,MATCH($A14,Scoring!$S$5:$S$12,0)) -> 3.9 | I14: =INDEX(Model!$P$5:$P$12,MATCH($A14,Scoring!$S$5:$S$12,0)) -> 0.045601625 | J14: =MIN(IF($L7=1,INDEX(Distances!$B$16:$I$23,MATCH($B14,Distances!$A$16:$A$23,0),MATCH($B7,Distances!$A$16:$A$23,0)),999),IF($L8=1,INDEX(Distances!$B$16:$I$23,MATCH($B14,Distances!$A$16:$A$23,0),MATCH($B8,Distances!$A$16:$A$23,0)),999),IF($L9=1,INDEX(Distances!$B$16:$I$23,MATCH($B14,Distances!$A$16:$A$23,0),MATCH($B9,Distances!$A$16:$A$23,0)),999),IF($L10=1,INDEX(Distances!$B$16:$I$23,MATCH($B14,Distances!$A$16:$A$23,0),MATCH($B10,Distances!$A$16:$A$23,0)),999),IF($L11=1,INDEX(Distances!$B$16:$I$23,MATCH($B14,Distances!$A$16:$A$23,0),MATCH($B11,Distances!$A$16:$A$23,0)),999),IF($L12=1,INDEX(Distances!$B$16:$I$23,MATCH($B14,Distances!$A$16:$A$23,0),MATCH($B12,Distances!$A$16:$A$23,0)),999),IF($L13=1,INDEX(Distances!$B$16:$I$23,MATCH($B14,Distances!$A$16:$A$23,0),MATCH($B13,Distances!$A$16:$A$23,0)),999)) -> 5.4895701 | K14: =SUMPRODUCT($L$7:$L13,$H$7:$H13) -> 7.26 | L14: =IF(AND(D14="Yes",K14+H14<=Assumptions!$B$34/10^7,J14>=Assumptions!$B$36),1,0) -> 0 | M14: =IF(L14=1,"OPEN",IF(D14="No",IF(INDEX(Model!$V$5:$V$12,MATCH($A14,Scoring!$S$5:$S$12,0))<=0,"Reject: negative incremental EBITDA","Reject: fails payback/NPV gate"),IF(J14<Assumptions!$B$36,"Hold: too close to a new pick","Reserve: next in line if budget grows"))) -> Reject: negative incremental EBITDA | N14: =INDEX(Scoring!$T$5:$T$12,MATCH($A14,Scoring!$S$5:$S$12,0)) -> Cannibalisation score | O14: =INDEX(Scoring!$U$5:$U$12,MATCH($A14,Scoring!$S$5:$S$12,0)) -> Profitability score | P14: =IF(L14=1,SUM($L$7:L14),0) -> 0
A16: How to read: green rows are recommended. Pink rows fail the financial gate, however attractive their footfall or income looks.
A17: Footfall trap: compare Marathahalli (highest footfall) with its NPV. Mostly commuter footfall with a low entry rate, high rent and 7 competitors.
A18: Cannibalisation trap: Bellandur and Hebbal have strong gross sales, but 15-20% would come from our own HSR Layout / Malleshwaram stores.
A19: Close call for slot 2: Whitefield (biggest sales, 7 competitors, high rent) vs Sarjapur Road (fastest growth, cheaper rent, poorer access). Shift weight to competition to see the flip.

Sheet Assumptions
A1: Assumptions and scenario levers
A2: Blue = editable. Sources / rationale in column D.
A3: Assumption | B3: Value | C3: Unit | D3: Source / rationale
A4: Average household size | B4: 3.8 | C4: persons | D4: Census 2011 urban Bengaluru: majority of households have 4 or fewer members; ~3.8 used.
A5: Grocery + FMCG wallet as % of household income | B5: 0.14 | C5: % | D5: HCES 2023-24: food is ~39.7% of urban consumption; consumption ~35-40% of income for affluent Bengaluru households -> ~14%.
A6: Organised-retail share of wallet: base | B6: 0.1 | C6: % | D6: Assumption: organised + online share rises with income.
A7: Organised share: increase per Rs 1,000 income | B7: 0.002 | C7: % per Rs 000 | D7: Assumption. Rs 1 lakh income -> 30% organised share.
A8: Organised share cap | B8: 0.4 | C8: % | D8: Assumption.
A9: Quick-commerce pull (equivalent competitor stores) | B9: 1.5 | C9: stores | D9: Assumption: Blinkit/Zepto/Instamart dark stores act like ~1.5 extra competitors in every catchment.
A10: Accessibility normaliser (score that equals one average competitor) | B10: 7 | C10: score | D10: Assumption: a site scoring 7/10 is as attractive as one competitor.
A11: Store entry rate: resident footfall | B11: 0.12 | C11: % | D11: Assumption, tuned on existing stores.
A12: Store entry rate: transit footfall | B12: 0.02 | C12: % | D12: Assumption: commuters passing a site rarely stop for groceries. This is why footfall != sales.
A13: Conversion: entrants who buy | B13: 0.75 | C13: % | D13: Assumption, typical supermarket walk-in conversion.
A14: Average bill: base | B14: 350 | C14: Rs | D14: Assumption.
A15: Average bill: increase per Rs 1,000 income | B15: 2.5 | C15: Rs | D15: Assumption. Rs 1 lakh income -> Rs 600 bill.
A16: Weight on wallet method (vs footfall method) | B16: 0.5 | C16: % | D16: Equal blend of two independent estimates.
A17: Trading days per year | B17: 365 | C17: days
A18: Standard store size | B18: 10000 | C18: sq ft | D18: Mid-format supermarket; held constant so sites compare like-for-like.
A19: Gross margin | B19: 0.21 | C19: % | D19: Assumption for mid-format grocery (value players such as DMart run ~15%).
A20: Staff cost per store per year | B20: 11000000 | C20: Rs | D20: ~45 staff x ~Rs 20,000/month.
A21: Other fixed opex (power, security, maintenance) | B21: 6000000 | C21: Rs/yr | D21: Assumption.
A22: Variable opex (shrinkage, packaging, payments, marketing) | B22: 0.05 | C22: % of sales | D22: Assumption. Yields store EBITDA of ~3-7% of sales, in line with Indian grocery.
A23: Fit-out capex | B23: 2200 | C23: Rs/sq ft | D23: Assumption.
A24: Security deposit | B24: 6 | C24: months rent | D24: Common Bengaluru commercial practice (6-10 months). Treated as cash out (conservative).
A25: Opening inventory | B25: 8000000 | C25: Rs | D25: Assumption.
A26: Rent escalation per year | B26: 0.05 | C26: % | D26: Typical 15% every 3 years ~ 5% p.a.
A27: Staff / fixed cost inflation per year | B27: 0.06 | C27: % | D27: Assumption.
A28: Sales ramp: year 1 (% of mature) | B28: 0.7 | C28: % | D28: Assumption.
A29: Sales ramp: year 2 | B29: 0.9 | C29: % | D29: Assumption.
... A36: Min distance between two new picks | B36: 5 | C36: km | D36: Avoid new stores cannibalising each other.
A38: Public benchmarks used for calibration
A39: MoSPI HCES 2023-24: urban average MPCE Rs 6,996; food share of urban MPCE ~39.7%. https://www.mospi.gov.in/sites/default/files/press_release/HCES_Report202324_Press_Note_30012025.pdf
A40: Census 2011: BBMP population ~8.44 million (198 wards). Ward-wise data: https://data.opencity.in/dataset/bengaluru-census-2011
A41: Bengaluru high-street retail rent Rs 176-326 /sq ft/month (2025); neighbourhood commercial Rs 45-180. https://apparelresources.com/business-news/retail/apparel-drives-25-retail-leasing-top-7-cities/
A42: Grocery store productivity: DMart revenue ~Rs 31,000-35,000 per sq ft per year, EBIT ~7-8%. https://tradebrains.in/how-did-dmart-become-the-most-profitable-retail-grocery-store-in-india/

Sheet Weights
A1: Scoring weights (must total 100%)
A2: Blue = editable. Each criterion is scaled 0-100 across the 8 candidates (min-max).
A3: Key | B3: Criterion | C3: Weight | D3: Direction | E3: Metric used | F3: Why it matters
A4: demand | B4: Demand potential | C4: 0.2 | D4: Higher better | E4: Calibrated gross sales (Rs Cr) | F4: Size of the prize.
A5: profit | B5: Profitability | C5: 0.3 | D5: Higher better | E5: 9-yr NPV after cannibalisation (Rs Cr) | F5: Turns footfall into money: captures rent, ramp-up and lost sales at existing stores.
A6: competition | B6: Competition intensity | C6: 0.1 | D6: Lower better | E6: Organised grocery stores within 2 km | F6: Price wars and share risk.
A7: rent | B7: Rent burden | C7: 0.1 | D7: Lower better | E7: Rent as % of sales | F7: Rent is the largest fixed cost and is locked in for 9 years.
A8: access | B8: Accessibility | C8: 0.1 | D8: Higher better | E8: Composite score 1-10 (metro, parking, road congestion) | F8: Drives repeat visits and basket size.
A9: cannib | B9: Cannibalisation | C9: 0.15 | D9: Lower better | E9: Share of new sales taken from our nearest store | F9: Gross sales overstate value if they come from ourselves.
A10: growth | B10: Catchment growth | C10: 0.05 | D10: Higher better | E10: Population growth % p.a. | F10: Future-proofs the lease.
B11: Total | C11: =SUM(C4:C10) -> 1 | D11: =IF(ROUND(C11,4)=1,"OK","Weights must total 100%") -> OK

Sheet Candidates
A1: Shortlisted candidate locations (inputs)
A2: Synthetic, calibrated to public benchmarks. Coordinates are real locality centroids (approx.).
A4: Location | B4: Latitude | C4: Longitude | D4: Population within 1.5 km | E4: Median household income (Rs/month) | F4: Daily footfall past site | G4: Resident share of footfall | H4: Organised competitors within 2 km | I4: Rent (Rs/sq ft/month) | J4: Accessibility (1-10) | K4: Catchment growth (% p.a.)
A5: Whitefield | B5: 12.9698 | C5: 77.75 | D5: 105000 | E5: 125000 | F5: 24000 | G5: 0.35 | H5: 7 | I5: 145 | J5: 8 | K5: 0.045
A6: Marathahalli | B6: 12.9569 | C6: 77.7011 | D6: 105000 | E6: 95000 | F6: 32000 | G6: 0.25 | H6: 7 | I6: 150 | J6: 6 | K6: 0.035
A7: Bellandur | B7: 12.926 | C7: 77.6762 | D7: 110000 | E7: 135000 | F7: 16000 | G7: 0.55 | H7: 5 | I7: 130 | J7: 4 | K7: 0.05
A8: Sarjapur Road | B8: 12.907 | C8: 77.699 | D8: 95000 | E8: 120000 | F8: 12000 | G8: 0.7 | H8: 3 | I8: 95 | J8: 5 | K8: 0.07
A9: Hebbal | B9: 13.0358 | C9: 77.597 | D9: 100000 | E9: 105000 | F9: 15000 | G9: 0.6 | H9: 4 | I9: 120 | J9: 7 | K9: 0.04
A10: Electronic City | B10: 12.8452 | C10: 77.6602 | D10: 90000 | E10: 95000 | F10: 20000 | G10: 0.4 | H10: 4 | I10: 75 | J10: 7 | K10: 0.05
A11: Kanakapura Road | B11: 12.8856 | C11: 77.564 | D11: 105000 | E11: 85000 | F11: 13000 | G11: 0.8 | H11: 2 | I11: 65 | J11: 8 | K11: 0.055
A12: Yelahanka | B12: 13.1007 | C12: 77.5963 | D12: 85000 | E12: 80000 | F12: 11000 | G12: 0.75 | H12: 2 | I12: 70 | J12: 6 | K12: 0.045
A14: Example row format: Whitefield | 12.9698 | 77.7500 | 105,000 | 125,000 | 24,000 | 35% | 7 | 145 | 8 | 4.5%
A15: Footfall = people passing the site per day (pedestrian + stopping vehicles). Resident share separates locals from commuters/transit.

Sheet Existing_Stores
A1: Existing stores: comparable performance and model calibration
A2: Same demand formulas as the Model sheet are run on existing stores; calibration factor = actual / predicted.
A4: Location | B4: Latitude | C4: Longitude | D4: Population within 1.5 km | E4: Median household income (Rs/month) | F4: Daily footfall past site | G4: Resident share of footfall | H4: Organised competitors within 2 km | I4: Rent (Rs/sq ft/month) | J4: Accessibility (1-10) | K4: Catchment growth (% p.a.) | L4: Actual annual sales (Rs Cr) | M4: Wallet method (Rs Cr) | N4: Footfall method (Rs Cr) | O4: Blended prediction (Rs Cr) | P4: Calibrated prediction (Rs Cr) | Q4: Abs % error
A5: Koramangala | B5: 12.9352 | C5: 77.6245 | D5: 110000 | E5: 115000 | F5: 19000 | G5: 0.55 | H5: 6 | I5: 165 | J5: 8 | K5: 0.02 | L5: 31.5 | M5: =(D5/Assumptions!$B$4)*(E5*Assumptions!$B$5)*MIN(Assumptions!$B$8,Assumptions!$B$6+Assumptions!$B$7*E5/1000)*((J5/Assumptions!$B$10)/((J5/Assumptions!$B$10)+H5+Assumptions!$B$9))*12/10^7 -> 24.404211 | N5: =((F5*G5*Assumptions!$B$11+F5*(1-G5)*Assumptions!$B$12)*Assumptions!$B$13)*(Assumptions!$B$14+Assumptions!$B$15*E5/1000)*Assumptions!$B$17/10^7 -> 24.868477 | O5: =Assumptions!$B$16*M5+(1-Assumptions!$B$16)*N5 -> 24.636344 | P5: =O5*$C$13 -> 31.405915 | Q5: =ABS(P5-L5)/L5 -> 0.0029868099
A6: Indiranagar | B6: 12.9784 | C6: 77.6408 | D6: 95000 | E6: 130000 | F6: 21000 | G6: 0.45 | H6: 6 | I6: 180 | J6: 9 | K6: 0.015 | L6: 30.2 | M6: =(D6/Assumptions!$B$4)*(E6*Assumptions!$B$5)*MIN(Assumptions!$B$8,Assumptions!$B$6+Assumptions!$B$7*E6/1000)*((J6/Assumptions!$B$10)/((J6/Assumptions!$B$10)+H6+Assumptions!$B$9))*12/10^7 -> 28.764878 | N6: =((F6*G6*Assumptions!$B$11+F6*(1-G6)*Assumptions!$B$12)*Assumptions!$B$13)*(Assumptions!$B$14+Assumptions!$B$15*E6/1000)*Assumptions!$B$17/10^7 -> 25.222641 | O6: =Assumptions!$B$16*M6+(1-Assumptions!$B$16)*N6 -> 26.993759 | P6: =O6*$C$13 -> 34.411102 | Q6: =ABS(P6-L6)/L6 -> 0.13944046
A7: Jayanagar | B7: 12.925 | C7: 77.5938 | D7: 120000 | E7: 95000 | F7: 17000 | G7: 0.7 | H7: 5 | I7: 140 | J7: 8 | K7: 0.01 | L7: 29.8 | M7: =(D7/Assumptions!$B$4)*(E7*Assumptions!$B$5)*MIN(Assumptions!$B$8,Assumptions!$B$6+Assumptions!$B$7*E7/1000)*((J7/Assumptions!$B$10)/((J7/Assumptions!$B$10)+H7+Assumptions!$B$9))*12/10^7 -> 21.855701 | N7: =((F7*G7*Assumptions!$B$11+F7*(1-G7)*Assumptions!$B$12)*Assumptions!$B$13)*(Assumptions!$B$14+Assumptions!$B$15*E7/1000)*Assumptions!$B$17/10^7 -> 24.606703 | O7: =Assumptions!$B$16*M7+(1-Assumptions!$B$16)*N7 -> 23.231202 | P7: =O7*$C$13 -> 29.614669 | Q7: =ABS(P7-L7)/L7 -> 0.0062191499
A8: Malleshwaram | B8: 13.0035 | C8: 77.5709 | D8: 100000 | E8: 90000 | F8: 15000 | G8: 0.7 | H8: 4 | I8: 130 | J8: 7 | K8: 0.01 | L8: 26.1 | M8: =(D8/Assumptions!$B$4)*(E8*Assumptions!$B$5)*MIN(Assumptions!$B$8,Assumptions!$B$6+Assumptions!$B$7*E8/1000)*((J8/Assumptions!$B$10)/((J8/Assumptions!$B$10)+H8+Assumptions!$B$9))*12/10^7 -> 17.140081 | N8: =((F8*G8*Assumptions!$B$11+F8*(1-G8)*Assumptions!$B$12)*Assumptions!$B$13)*(Assumptions!$B$14+Assumptions!$B$15*E8/1000)*Assumptions!$B$17/10^7 -> 21.249844 | O8: =Assumptions!$B$16*M8+(1-Assumptions!$B$16)*N8 -> 19.194962 | P8: =O8*$C$13 -> 24.469352 | Q8: =ABS(P8-L8)/L8 -> 0.062476929
A9: HSR Layout | B9: 12.9116 | C9: 77.6474 | D9: 105000 | E9: 110000 | F9: 16000 | G9: 0.65 | H9: 5 | I9: 120 | J9: 6 | K9: 0.03 | L9: 28.4 | M9: =(D9/Assumptions!$B$4)*(E9*Assumptions!$B$5)*MIN(Assumptions!$B$8,Assumptions!$B$6+Assumptions!$B$7*E9/1000)*((J9/Assumptions!$B$10)/((J9/Assumptions!$B$10)+H9+Assumptions!$B$9))*12/10^7 -> 19.037138 | N9: =((F9*G9*Assumptions!$B$11+F9*(1-G9)*Assumptions!$B$12)*Assumptions!$B$13)*(Assumptions!$B$14+Assumptions!$B$15*E9/1000)*Assumptions!$B$17/10^7 -> 23.26875 | O9: =Assumptions!$B$16*M9+(1-Assumptions!$B$16)*N9 -> 21.152944 | P9: =O9*$C$13 -> 26.965348 | Q9: =ABS(P9-L9)/L9 -> 0.050515913
A10: Rajajinagar | B10: 12.9915 | C10: 77.5545 | D10: 115000 | E10: 80000 | F10: 14000 | G10: 0.75 | H10: 4 | I10: 110 | J10: 7 | K10: 0.01 | L10: 24 | M10: =(D10/Assumptions!$B$4)*(E10*Assumptions!$B$5)*MIN(Assumptions!$B$8,Assumptions!$B$6+Assumptions!$B$7*E10/1000)*((J10/Assumptions!$B$10)/((J10/Assumptions!$B$10)+H10+Assumptions!$B$9))*12/10^7 -> 16.269474 | N10: =((F10*G10*Assumptions!$B$11+F10*(1-G10)*Assumptions!$B$12)*Assumptions!$B$13)*(Assumptions!$B$14+Assumptions!$B$15*E10/1000)*Assumptions!$B$17/10^7 -> 20.024812 | O10: =Assumptions!$B$16*M10+(1-Assumptions!$B$16)*N10 -> 18.147143 | P10: =O10*$C$13 -> 23.133613 | Q10: =ABS(P10-L10)/L10 -> 0.03609945
A13: Calibration factor (actual / predicted) | C13: =SUM(L5:L10)/SUM(O5:O10) -> 1.2747799
A14: Mean absolute % error after calibration | C14: =AVERAGE(Q5:Q10) -> 0.049623118
A16: Read: the raw model under-predicts mature stores (they have loyalty the formula cannot see), so candidate sales are scaled by the factor. Error after calibration is the model's credibility check.

Sheet Distances
A1: Distances (km, haversine from coordinates)
A2: Top: candidate to each existing store. Bottom: candidate to candidate (used to stop two new picks cannibalising each other).
A4: Candidate | B4: Koramangala | C4: Indiranagar | D4: Jayanagar | E4: Malleshwaram | F4: HSR Layout | G4: Rajajinagar | H4: Nearest existing store | I4: Distance (km)
A5: =Candidates!A5 -> Whitefield | B5: =2*6371*ASIN(SQRT(SIN(RADIANS(Existing_Stores!$B$5-Candidates!$B$5)/2)^2+COS(RADIANS(Candidates!$B$5))*COS(RADIANS(Existing_Stores!$B$5))*SIN(RADIANS(Existing_Stores!$C$5-Candidates!$C$5)/2)^2)) -> 14.133621 | C5: =2*6371*ASIN(SQRT(SIN(RADIANS(Existing_Stores!$B$6-Candidates!$B$5)/2)^2+COS(RADIANS(Candidates!$B$5))*COS(RADIANS(Existing_Stores!$B$6))*SIN(RADIANS(Existing_Stores!$C$6-Candidates!$C$5)/2)^2)) -> 11.871087 | D5: =2*6371*ASIN(SQRT(SIN(RADIANS(Existing_Stores!$B$7-Candidates!$B$5)/2)^2+COS(RADIANS(Candidates!$B$5))*COS(RADIANS(Existing_Stores!$B$7))*SIN(RADIANS(Existing_Stores!$C$7-Candidates!$C$5)/2)^2)) -> 17.644867 | E5: =2*6371*ASIN(SQRT(SIN(RADIANS(Existing_Stores!$B$8-Candidates!$B$5)/2)^2+COS(RADIANS(Candidates!$B$5))*COS(RADIANS(Existing_Stores!$B$8))*SIN(RADIANS(Existing_Stores!$C$8-Candidates!$C$5)/2)^2)) -> 19.764125 | F5: =2*6371*ASIN(SQRT(SIN(RADIANS(Existing_Stores!$B$9-Candidates!$B$5)/2)^2+COS(RADIANS(Candidates!$B$5))*COS(RADIANS(Existing_Stores!$B$9))*SIN(RADIANS(Existing_Stores!$C$9-Candidates!$C$5)/2)^2)) -> 12.865056 | G5: =2*6371*ASIN(SQRT(SIN(RADIANS(Existing_Stores!$B$10-Candidates!$B$5)/2)^2+COS(RADIANS(Candidates!$B$5))*COS(RADIANS(Existing_Stores!$B$10))*SIN(RADIANS(Existing_Stores!$C$10-Candidates!$C$5)/2)^2)) -> 21.320082 | H5: =INDEX($B$4:$G$4,MATCH(MIN(B5:G5),B5:G5,0)) -> Indiranagar | I5: =MIN(B5:G5) -> 11.871087
A6: =Candidates!A6 -> Marathahalli | B6: =2*6371*ASIN(SQRT(SIN(RADIANS(Existing_Stores!$B$5-Candidates!$B$6)/2)^2+COS(RADIANS(Candidates!$B$6))*COS(RADIANS(Existing_Stores!$B$5))*SIN(RADIANS(Existing_Stores!$C$5-Candidates!$C$6)/2)^2)) -> 8.6446108 | C6: =2*6371*ASIN(SQRT(SIN(RADIANS(Existing_Stores!$B$6-Candidates!$B$6)/2)^2+COS(RADIANS(Candidates!$B$6))*COS(RADIANS(Existing_Stores!$B$6))*SIN(RADIANS(Existing_Stores!$C$6-Candidates!$C$6)/2)^2)) -> 6.9576771 | D6: =2*6371*ASIN(SQRT(SIN(RADIANS(Existing_Stores!$B$7-Candidates!$B$6)/2)^2+COS(RADIANS(Candidates!$B$6))*COS(RADIANS(Existing_Stores!$B$7))*SIN(RADIANS(Existing_Stores!$C$7-Candidates!$C$6)/2)^2)) -> 12.157162 | E6: =2*6371*ASIN(SQRT(SIN(RADIANS(Existing_Stores!$B$8-Candidates!$B$6)/2)^2+COS(RADIANS(Candidates!$B$6))*COS(RADIANS(Existing_Stores!$B$8))*SIN(RADIANS(Existing_Stores!$C$8-Candidates!$C$6)/2)^2)) -> 15.029154 | F6: =2*6371*ASIN(SQRT(SIN(RADIANS(Existing_Stores!$B$9-Candidates!$B$6)/2)^2+COS(RADIANS(Candidates!$B$6))*COS(RADIANS(Existing_Stores!$B$9))*SIN(RADIANS(Existing_Stores!$C$9-Candidates!$C$6)/2)^2)) -> 7.6968288 | G6: =2*6371*ASIN(SQRT(SIN(RADIANS(Existing_Stores!$B$10-Candidates!$B$6)/2)^2+COS(RADIANS(Candidates!$B$6))*COS(RADIANS(Existing_Stores!$B$10))*SIN(RADIANS(Existing_Stores!$C$10-Candidates!$C$6)/2)^2)) -> 16.3443 | H6: =INDEX($B$4:$G$4,MATCH(MIN(B6:G6),B6:G6,0)) -> Indiranagar | I6: =MIN(B6:G6) -> 6.9576771
A7: =Candidates!A7 -> Bellandur | B7: =2*6371*ASIN(SQRT(SIN(RADIANS(Existing_Stores!$B$5-Candidates!$B$7)/2)^2+COS(RADIANS(Candidates!$B$7))*COS(RADIANS(Existing_Stores!$B$5))*SIN(RADIANS(Existing_Stores!$C$5-Candidates!$C$7)/2)^2)) -> 5.6956224 | C7: =2*6371*ASIN(SQRT(SIN(RADIANS(Existing_Stores!$B$6-Candidates!$B$7)/2)^2+COS(RADIANS(Candidates!$B$7))*COS(RADIANS(Existing_Stores!$B$6))*SIN(RADIANS(Existing_Stores!$C$6-Candidates!$C$7)/2)^2)) -> 6.976065 | D7: =2*6371*ASIN(SQRT(SIN(RADIANS(Existing_Stores!$B$7-Candidates!$B$7)/2)^2+COS(RADIANS(Candidates!$B$7))*COS(RADIANS(Existing_Stores!$B$7))*SIN(RADIANS(Existing_Stores!$C$7-Candidates!$C$7)/2)^2)) -> 8.9309933 | E7: =2*6371*ASIN(SQRT(SIN(RADIANS(Existing_Stores!$B$8-Candidates!$B$7)/2)^2+COS(RADIANS(Candidates!$B$7))*COS(RADIANS(Existing_Stores!$B$8))*SIN(RADIANS(Existing_Stores!$C$8-Candidates!$C$7)/2)^2)) -> 14.298921 | F7: =2*6371*ASIN(SQRT(SIN(RADIANS(Existing_Stores!$B$9-Candidates!$B$7)/2)^2+COS(RADIANS(Candidates!$B$7))*COS(RADIANS(Existing_Stores!$B$9))*SIN(RADIANS(Existing_Stores!$C$9-Candidates!$C$7)/2)^2)) -> 3.5080927 | G7: =2*6371*ASIN(SQRT(SIN(RADIANS(Existing_Stores!$B$10-Candidates!$B$7)/2)^2+COS(RADIANS(Candidates!$B$7))*COS(RADIANS(Existing_Stores!$B$10))*SIN(RADIANS(Existing_Stores!$C$10-Candidates!$C$7)/2)^2)) -> 15.065304 | H7: =INDEX($B$4:$G$4,MATCH(MIN(B7:G7),B7:G7,0)) -> HSR Layout | I7: =MIN(B7:G7) -> 3.5080927
A8: =Candidates!A8 -> Sarjapur Road | B8: =2*6371*ASIN(SQRT(SIN(RADIANS(Existing_Stores!$B$5-Candidates!$B$8)/2)^2+COS(RADIANS(Candidates!$B$8))*COS(RADIANS(Existing_Stores!$B$5))*SIN(RADIANS(Existing_Stores!$C$5-Candidates!$C$8)/2)^2)) -> 8.661772 | C8: =2*6371*ASIN(SQRT(SIN(RADIANS(Existing_Stores!$B$6-Candidates!$B$8)/2)^2+COS(RADIANS(Candidates!$B$8))*COS(RADIANS(Existing_Stores!$B$6))*SIN(RADIANS(Existing_Stores!$C$6-Candidates!$C$8)/2)^2)) -> 10.139659 | D8: =2*6371*ASIN(SQRT(SIN(RADIANS(Existing_Stores!$B$7-Candidates!$B$8)/2)^2+COS(RADIANS(Candidates!$B$8))*COS(RADIANS(Existing_Stores!$B$7))*SIN(RADIANS(Existing_Stores!$C$7-Candidates!$C$8)/2)^2)) -> 11.576084 | E8: =2*6371*ASIN(SQRT(SIN(RADIANS(Existing_Stores!$B$8-Candidates!$B$8)/2)^2+COS(RADIANS(Candidates!$B$8))*COS(RADIANS(Existing_Stores!$B$8))*SIN(RADIANS(Existing_Stores!$C$8-Candidates!$C$8)/2)^2)) -> 17.545238 | F8: =2*6371*ASIN(SQRT(SIN(RADIANS(Existing_Stores!$B$9-Candidates!$B$8)/2)^2+COS(RADIANS(Candidates!$B$8))*COS(RADIANS(Existing_Stores!$B$9))*SIN(RADIANS(Existing_Stores!$C$9-Candidates!$C$8)/2)^2)) -> 5.6159803 | G8: =2*6371*ASIN(SQRT(SIN(RADIANS(Existing_Stores!$B$10-Candidates!$B$8)/2)^2+COS(RADIANS(Candidates!$B$8))*COS(RADIANS(Existing_Stores!$B$10))*SIN(RADIANS(Existing_Stores!$C$10-Candidates!$C$8)/2)^2)) -> 18.26171 | H8: =INDEX($B$4:$G$4,MATCH(MIN(B8:G8),B8:G8,0)) -> HSR Layout | I8: =MIN(B8:G8) -> 5.6159803
A9: =Candidates!A9 -> Hebbal | B9: =2*6371*ASIN(SQRT(SIN(RADIANS(Existing_Stores!$B$5-Candidates!$B$9)/2)^2+COS(RADIANS(Candidates!$B$9))*COS(RADIANS(Existing_Stores!$B$5))*SIN(RADIANS(Existing_Stores!$C$5-Candidates!$C$9)/2)^2)) -> 11.576254 | C9: =2*6371*ASIN(SQRT(SIN(RADIANS(Existing_Stores!$B$6-Candidates!$B$9)/2)^2+COS(RADIANS(Candidates!$B$9))*COS(RADIANS(Existing_Stores!$B$6))*SIN(RADIANS(Existing_Stores!$C$6-Candidates!$C$9)/2)^2)) -> 7.9533657 | D9: =2*6371*ASIN(SQRT(SIN(RADIANS(Existing_Stores!$B$7-Candidates!$B$9)/2)^2+COS(RADIANS(Candidates!$B$9))*COS(RADIANS(Existing_Stores!$B$7))*SIN(RADIANS(Existing_Stores!$C$7-Candidates!$C$9)/2)^2)) -> 12.325276 | E9: =2*6371*ASIN(SQRT(SIN(RADIANS(Existing_Stores!$B$8-Candidates!$B$9)/2)^2+COS(RADIANS(Candidates!$B$9))*COS(RADIANS(Existing_Stores!$B$8))*SIN(RADIANS(Existing_Stores!$C$8-Candidates!$C$9)/2)^2)) -> 4.5710803 | F9: =2*6371*ASIN(SQRT(SIN(RADIANS(Existing_Stores!$B$9-Candidates!$B$9)/2)^2+COS(RADIANS(Candidates!$B$9))*COS(RADIANS(Existing_Stores!$B$9))*SIN(RADIANS(Existing_Stores!$C$9-Candidates!$C$9)/2)^2)) -> 14.850985 | G9: =2*6371*ASIN(SQRT(SIN(RADIANS(Existing_Stores!$B$10-Candidates!$B$9)/2)^2+COS(RADIANS(Candidates!$B$9))*COS(RADIANS(Existing_Stores!$B$10))*SIN(RADIANS(Existing_Stores!$C$10-Candidates!$C$9)/2)^2)) -> 6.7428053 | H9: =INDEX($B$4:$G$4,MATCH(MIN(B9:G9),B9:G9,0)) -> Malleshwaram | I9: =MIN(B9:G9) -> 4.5710803
A10: =Candidates!A10 -> Electronic City | B10: =2*6371*ASIN(SQRT(SIN(RADIANS(Existing_Stores!$B$5-Candidates!$B$10)/2)^2+COS(RADIANS(Candidates!$B$10))*COS(RADIANS(Existing_Stores!$B$5))*SIN(RADIANS(Existing_Stores!$C$5-Candidates!$C$10)/2)^2)) -> 10.729627 | C10: =2*6371*ASIN(SQRT(SIN(RADIANS(Existing_Stores!$B$6-Candidates!$B$10)/2)^2+COS(RADIANS(Candidates!$B$10))*COS(RADIANS(Existing_Stores!$B$6))*SIN(RADIANS(Existing_Stores!$C$6-Candidates!$C$10)/2)^2)) -> 14.959668 | D10: =2*6371*ASIN(SQRT(SIN(RADIANS(Existing_Stores!$B$7-Candidates!$B$10)/2)^2+COS(RADIANS(Candidates!$B$10))*COS(RADIANS(Existing_Stores!$B$7))*SIN(RADIANS(Existing_Stores!$C$7-Candidates!$C$10)/2)^2)) -> 11.425382 | E10: =2*6371*ASIN(SQRT(SIN(RADIANS(Existing_Stores!$B$8-Candidates!$B$10)/2)^2+COS(RADIANS(Candidates!$B$10))*COS(RADIANS(Existing_Stores!$B$8))*SIN(RADIANS(Existing_Stores!$C$8-Candidates!$C$10)/2)^2)) -> 20.08737 | F10: =2*6371*ASIN(SQRT(SIN(RADIANS(Existing_Stores!$B$9-Candidates!$B$10)/2)^2+COS(RADIANS(Candidates!$B$10))*COS(RADIANS(Existing_Stores!$B$9))*SIN(RADIANS(Existing_Stores!$C$9-Candidates!$C$10)/2)^2)) -> 7.5125822 | G10: =2*6371*ASIN(SQRT(SIN(RADIANS(Existing_Stores!$B$10-Candidates!$B$10)/2)^2+COS(RADIANS(Candidates!$B$10))*COS(RADIANS(Existing_Stores!$B$10))*SIN(RADIANS(Existing_Stores!$C$10-Candidates!$C$10)/2)^2)) -> 19.896676 | H10: =INDEX($B$4:$G$4,MATCH(MIN(B10:G10),B10:G10,0)) -> HSR Layout | I10: =MIN(B10:G10) -> 7.5125822
A11: =Candidates!A11 -> Kanakapura Road | B11: =2*6371*ASIN(SQRT(SIN(RADIANS(Existing_Stores!$B$5-Candidates!$B$11)/2)^2+COS(RADIANS(Candidates!$B$11))*COS(RADIANS(Existing_Stores!$B$5))*SIN(RADIANS(Existing_Stores!$C$5-Candidates!$C$11)/2)^2)) -> 8.5682826 | C11: =2*6371*ASIN(SQRT(SIN(RADIANS(Existing_Stores!$B$6-Candidates!$B$11)/2)^2+COS(RADIANS(Candidates!$B$11))*COS(RADIANS(Existing_Stores!$B$6))*SIN(RADIANS(Existing_Stores!$C$6-Candidates!$C$11)/2)^2)) -> 13.257248 | D11: =2*6371*ASIN(SQRT(SIN(RADIANS(Existing_Stores!$B$7-Candidates!$B$11)/2)^2+COS(RADIANS(Candidates!$B$11))*COS(RADIANS(Existing_Stores!$B$7))*SIN(RADIANS(Existing_Stores!$C$7-Candidates!$C$11)/2)^2)) -> 5.4429931 | E11: =2*6371*ASIN(SQRT(SIN(RADIANS(Existing_Stores!$B$8-Candidates!$B$11)/2)^2+COS(RADIANS(Candidates!$B$11))*COS(RADIANS(Existing_Stores!$B$8))*SIN(RADIANS(Existing_Stores!$C$8-Candidates!$C$11)/2)^2)) -> 13.131189 | F11: =2*6371*ASIN(SQRT(SIN(RADIANS(Existing_Stores!$B$9-Candidates!$B$11)/2)^2+COS(RADIANS(Candidates!$B$11))*COS(RADIANS(Existing_Stores!$B$9))*SIN(RADIANS(Existing_Stores!$C$9-Candidates!$C$11)/2)^2)) -> 9.4907097 | G11: =2*6371*ASIN(SQRT(SIN(RADIANS(Existing_Stores!$B$10-Candidates!$B$11)/2)^2+COS(RADIANS(Candidates!$B$11))*COS(RADIANS(Existing_Stores!$B$10))*SIN(RADIANS(Existing_Stores!$C$10-Candidates!$C$11)/2)^2)) -> 11.820463 | H11: =INDEX($B$4:$G$4,MATCH(MIN(B11:G11),B11:G11,0)) -> Jayanagar | I11: =MIN(B11:G11) -> 5.4429931
A12: =Candidates!A12 -> Yelahanka | B12: =2*6371*ASIN(SQRT(SIN(RADIANS(Existing_Stores!$B$5-Candidates!$B$12)/2)^2+COS(RADIANS(Candidates!$B$12))*COS(RADIANS(Existing_Stores!$B$5))*SIN(RADIANS(Existing_Stores!$C$5-Candidates!$C$12)/2)^2)) -> 18.654631 | C12: =2*6371*ASIN(SQRT(SIN(RADIANS(Existing_Stores!$B$6-Candidates!$B$12)/2)^2+COS(RADIANS(Candidates!$B$12))*COS(RADIANS(Existing_Stores!$B$6))*SIN(RADIANS(Existing_Stores!$C$6-Candidates!$C$12)/2)^2)) -> 14.428257 | D12: =2*6371*ASIN(SQRT(SIN(RADIANS(Existing_Stores!$B$7-Candidates!$B$12)/2)^2+COS(RADIANS(Candidates!$B$12))*COS(RADIANS(Existing_Stores!$B$7))*SIN(RADIANS(Existing_Stores!$C$7-Candidates!$C$12)/2)^2)) -> 19.538826 | E12: =2*6371*ASIN(SQRT(SIN(RADIANS(Existing_Stores!$B$8-Candidates!$B$12)/2)^2+COS(RADIANS(Candidates!$B$12))*COS(RADIANS(Existing_Stores!$B$8))*SIN(RADIANS(Existing_Stores!$C$8-Candidates!$C$12)/2)^2)) -> 11.152854 | F12: =2*6371*ASIN(SQRT(SIN(RADIANS(Existing_Stores!$B$9-Candidates!$B$12)/2)^2+COS(RADIANS(Candidates!$B$12))*COS(RADIANS(Existing_Stores!$B$9))*SIN(RADIANS(Existing_Stores!$C$9-Candidates!$C$12)/2)^2)) -> 21.743587 | G12: =2*6371*ASIN(SQRT(SIN(RADIANS(Existing_Stores!$B$10-Candidates!$B$12)/2)^2+COS(RADIANS(Candidates!$B$12))*COS(RADIANS(Existing_Stores!$B$10))*SIN(RADIANS(Existing_Stores!$C$10-Candidates!$C$12)/2)^2)) -> 12.959265 | H12: =INDEX($B$4:$G$4,MATCH(MIN(B12:G12),B12:G12,0)) -> Malleshwaram | I12: =MIN(B12:G12) -> 11.152854
A15: Candidate | B15: Whitefield | C15: Marathahalli | D15: Bellandur | E15: Sarjapur Road | F15: Hebbal | G15: Electronic City | H15: Kanakapura Road | I15: Yelahanka
A16: =Candidates!A5 -> Whitefield | B16: =2*6371*ASIN(SQRT(SIN(RADIANS(Candidates!$B$5-Candidates!$B$5)/2)^2+COS(RADIANS(Candidates!$B$5))*COS(RADIANS(Candidates!$B$5))*SIN(RADIANS(Candidates!$C$5-Candidates!$C$5)/2)^2)) -> 0 | C16: =2*6371*ASIN(SQRT(SIN(RADIANS(Candidates!$B$6-Candidates!$B$5)/2)^2+COS(RADIANS(Candidates!$B$5))*COS(RADIANS(Candidates!$B$6))*SIN(RADIANS(Candidates!$C$6-Candidates!$C$5)/2)^2)) -> 5.4895701 | D16: =2*6371*ASIN(SQRT(SIN(RADIANS(Candidates!$B$7-Candidates!$B$5)/2)^2+COS(RADIANS(Candidates!$B$5))*COS(RADIANS(Candidates!$B$7))*SIN(RADIANS(Candidates!$C$7-Candidates!$C$5)/2)^2)) -> 9.3638017 | E16: =2*6371*ASIN(SQRT(SIN(RADIANS(Candidates!$B$8-Candidates!$B$5)/2)^2+COS(RADIANS(Candidates!$B$5))*COS(RADIANS(Candidates!$B$8))*SIN(RADIANS(Candidates!$C$8-Candidates!$C$5)/2)^2)) -> 8.905627 | F16: =2*6371*ASIN(SQRT(SIN(RADIANS(Candidates!$B$9-Candidates!$B$5)/2)^2+COS(RADIANS(Candidates!$B$5))*COS(RADIANS(Candidates!$B$9))*SIN(RADIANS(Candidates!$C$9-Candidates!$C$5)/2)^2)) -> 18.128501 | G16: =2*6371*ASIN(SQRT(SIN(RADIANS(Candidates!$B$10-Candidates!$B$5)/2)^2+COS(RADIANS(Candidates!$B$5))*COS(RADIANS(Candidates!$B$10))*SIN(RADIANS(Candidates!$C$10-Candidates!$C$5)/2)^2)) -> 16.931895 | H16: =2*6371*ASIN(SQRT(SIN(RADIANS(Candidates!$B$11-Candidates!$B$5)/2)^2+COS(RADIANS(Candidates!$B$5))*COS(RADIANS(Candidates!$B$11))*SIN(RADIANS(Candidates!$C$11-Candidates!$C$5)/2)^2)) -> 22.226211 | I16: =2*6371*ASIN(SQRT(SIN(RADIANS(Candidates!$B$12-Candidates!$B$5)/2)^2+COS(RADIANS(Candidates!$B$5))*COS(RADIANS(Candidates!$B$12))*SIN(RADIANS(Candidates!$C$12-Candidates!$C$5)/2)^2)) -> 22.115405
A17: =Candidates!A6 -> Marathahalli | B17: =2*6371*ASIN(SQRT(SIN(RADIANS(Candidates!$B$5-Candidates!$B$6)/2)^2+COS(RADIANS(Candidates!$B$6))*COS(RADIANS(Candidates!$B$5))*SIN(RADIANS(Candidates!$C$5-Candidates!$C$6)/2)^2)) -> 5.4895701 | C17: =2*6371*ASIN(SQRT(SIN(RADIANS(Candidates!$B$6-Candidates!$B$6)/2)^2+COS(RADIANS(Candidates!$B$6))*COS(RADIANS(Candidates!$B$6))*SIN(RADIANS(Candidates!$C$6-Candidates!$C$6)/2)^2)) -> 0 | D17: =2*6371*ASIN(SQRT(SIN(RADIANS(Candidates!$B$7-Candidates!$B$6)/2)^2+COS(RADIANS(Candidates!$B$6))*COS(RADIANS(Candidates!$B$7))*SIN(RADIANS(Candidates!$C$7-Candidates!$C$6)/2)^2)) -> 4.3688751 | E17: =2*6371*ASIN(SQRT(SIN(RADIANS(Candidates!$B$8-Candidates!$B$6)/2)^2+COS(RADIANS(Candidates!$B$6))*COS(RADIANS(Candidates!$B$8))*SIN(RADIANS(Candidates!$C$8-Candidates!$C$6)/2)^2)) -> 5.5532923 | F17: =2*6371*ASIN(SQRT(SIN(RADIANS(Candidates!$B$9-Candidates!$B$6)/2)^2+COS(RADIANS(Candidates!$B$6))*COS(RADIANS(Candidates!$B$9))*SIN(RADIANS(Candidates!$C$9-Candidates!$C$6)/2)^2)) -> 14.289282 | G17: =2*6371*ASIN(SQRT(SIN(RADIANS(Candidates!$B$10-Candidates!$B$6)/2)^2+COS(RADIANS(Candidates!$B$6))*COS(RADIANS(Candidates!$B$10))*SIN(RADIANS(Candidates!$C$10-Candidates!$C$6)/2)^2)) -> 13.187883 | H17: =2*6371*ASIN(SQRT(SIN(RADIANS(Candidates!$B$11-Candidates!$B$6)/2)^2+COS(RADIANS(Candidates!$B$6))*COS(RADIANS(Candidates!$B$11))*SIN(RADIANS(Candidates!$C$11-Candidates!$C$6)/2)^2)) -> 16.841622 | I17: =2*6371*ASIN(SQRT(SIN(RADIANS(Candidates!$B$12-Candidates!$B$6)/2)^2+COS(RADIANS(Candidates!$B$6))*COS(RADIANS(Candidates!$B$12))*SIN(RADIANS(Candidates!$C$12-Candidates!$C$6)/2)^2)) -> 19.610472
A18: =Candidates!A7 -> Bellandur | B18: =2*6371*ASIN(SQRT(SIN(RADIANS(Candidates!$B$5-Candidates!$B$7)/2)^2+COS(RADIANS(Candidates!$B$7))*COS(RADIANS(Candidates!$B$5))*SIN(RADIANS(Candidates!$C$5-Candidates!$C$7)/2)^2)) -> 9.3638017 | C18: =2*6371*ASIN(SQRT(SIN(RADIANS(Candidates!$B$6-Candidates!$B$7)/2)^2+COS(RADIANS(Candidates!$B$7))*COS(RADIANS(Candidates!$B$6))*SIN(RADIANS(Candidates!$C$6-Candidates!$C$7)/2)^2)) -> 4.3688751 | D18: =2*6371*ASIN(SQRT(SIN(RADIANS(Candidates!$B$7-Candidates!$B$7)/2)^2+COS(RADIANS(Candidates!$B$7))*COS(RADIANS(Candidates!$B$7))*SIN(RADIANS(Candidates!$C$7-Candidates!$C$7)/2)^2)) -> 0 | E18: =2*6371*ASIN(SQRT(SIN(RADIANS(Candidates!$B$8-Candidates!$B$7)/2)^2+COS(RADIANS(Candidates!$B$7))*COS(RADIANS(Candidates!$B$8))*SIN(RADIANS(Candidates!$C$8-Candidates!$C$7)/2)^2)) -> 3.2511268 | F18: =2*6371*ASIN(SQRT(SIN(RADIANS(Candidates!$B$9-Candidates!$B$7)/2)^2+COS(RADIANS(Candidates!$B$7))*COS(RADIANS(Candidates!$B$9))*SIN(RADIANS(Candidates!$C$9-Candidates!$C$7)/2)^2)) -> 14.923411 | G18: =2*6371*ASIN(SQRT(SIN(RADIANS(Candidates!$B$10-Candidates!$B$7)/2)^2+COS(RADIANS(Candidates!$B$7))*COS(RADIANS(Candidates!$B$10))*SIN(RADIANS(Candidates!$C$10-Candidates!$C$7)/2)^2)) -> 9.1504093 | H18: =2*6371*ASIN(SQRT(SIN(RADIANS(Candidates!$B$11-Candidates!$B$7)/2)^2+COS(RADIANS(Candidates!$B$7))*COS(RADIANS(Candidates!$B$11))*SIN(RADIANS(Candidates!$C$11-Candidates!$C$7)/2)^2)) -> 12.964112 | I18: =2*6371*ASIN(SQRT(SIN(RADIANS(Candidates!$B$12-Candidates!$B$7)/2)^2+COS(RADIANS(Candidates!$B$7))*COS(RADIANS(Candidates!$B$12))*SIN(RADIANS(Candidates!$C$12-Candidates!$C$7)/2)^2)) -> 21.267143
A19: =Candidates!A8 -> Sarjapur Road | B19: =2*6371*ASIN(SQRT(SIN(RADIANS(Candidates!$B$5-Candidates!$B$8)/2)^2+COS(RADIANS(Candidates!$B$8))*COS(RADIANS(Candidates!$B$5))*SIN(RADIANS(Candidates!$C$5-Candidates!$C$8)/2)^2)) -> 8.905627 | C19: =2*6371*ASIN(SQRT(SIN(RADIANS(Candidates!$B$6-Candidates!$B$8)/2)^2+COS(RADIANS(Candidates!$B$8))*COS(RADIANS(Candidates!$B$6))*SIN(RADIANS(Candidates!$C$6-Candidates!$C$8)/2)^2)) -> 5.5532923 | D19: =2*6371*ASIN(SQRT(SIN(RADIANS(Candidates!$B$7-Candidates!$B$8)/2)^2+COS(RADIANS(Candidates!$B$8))*COS(RADIANS(Candidates!$B$7))*SIN(RADIANS(Candidates!$C$7-Candidates!$C$8)/2)^2)) -> 3.2511268 | E19: =2*6371*ASIN(SQRT(SIN(RADIANS(Candidates!$B$8-Candidates!$B$8)/2)^2+COS(RADIANS(Candidates!$B$8))*COS(RADIANS(Candidates!$B$8))*SIN(RADIANS(Candidates!$C$8-Candidates!$C$8)/2)^2)) -> 0 | F19: =2*6371*ASIN(SQRT(SIN(RADIANS(Candidates!$B$9-Candidates!$B$8)/2)^2+COS(RADIANS(Candidates!$B$8))*COS(RADIANS(Candidates!$B$9))*SIN(RADIANS(Candidates!$C$9-Candidates!$C$8)/2)^2)) -> 18.090713 | G19: =2*6371*ASIN(SQRT(SIN(RADIANS(Candidates!$B$10-Candidates!$B$8)/2)^2+COS(RADIANS(Candidates!$B$8))*COS(RADIANS(Candidates!$B$10))*SIN(RADIANS(Candidates!$C$10-Candidates!$C$8)/2)^2)) -> 8.0567771 | H19: =2*6371*ASIN(SQRT(SIN(RADIANS(Candidates!$B$11-Candidates!$B$8)/2)^2+COS(RADIANS(Candidates!$B$8))*COS(RADIANS(Candidates!$B$11))*SIN(RADIANS(Candidates!$C$11-Candidates!$C$8)/2)^2)) -> 14.824885 | I19: =2*6371*ASIN(SQRT(SIN(RADIANS(Candidates!$B$12-Candidates!$B$8)/2)^2+COS(RADIANS(Candidates!$B$8))*COS(RADIANS(Candidates!$B$12))*SIN(RADIANS(Candidates!$C$12-Candidates!$C$8)/2)^2)) -> 24.242772
A20: =Candidates!A9 -> Hebbal | B20: =2*6371*ASIN(SQRT(SIN(RADIANS(Candidates!$B$5-Candidates!$B$9)/2)^2+COS(RADIANS(Candidates!$B$9))*COS(RADIANS(Candidates!$B$5))*SIN(RADIANS(Candidates!$C$5-Candidates!$C$9)/2)^2)) -> 18.128501 | C20: =2*6371*ASIN(SQRT(SIN(RADIANS(Candidates!$B$6-Candidates!$B$9)/2)^2+COS(RADIANS(Candidates!$B$9))*COS(RADIANS(Candidates!$B$6))*SIN(RADIANS(Candidates!$C$6-Candidates!$C$9)/2)^2)) -> 14.289282 | D20: =2*6371*ASIN(SQRT(SIN(RADIANS(Candidates!$B$7-Candidates!$B$9)/2)^2+COS(RADIANS(Candidates!$B$9))*COS(RADIANS(Candidates!$B$7))*SIN(RADIANS(Candidates!$C$7-Candidates!$C$9)/2)^2)) -> 14.923411 | E20: =2*6371*ASIN(SQRT(SIN(RADIANS(Candidates!$B$8-Candidates!$B$9)/2)^2+COS(RADIANS(Candidates!$B$9))*COS(RADIANS(Candidates!$B$8))*SIN(RADIANS(Candidates!$C$8-Candidates!$C$9)/2)^2)) -> 18.090713 | F20: =2*6371*ASIN(SQRT(SIN(RADIANS(Candidates!$B$9-Candidates!$B$9)/2)^2+COS(RADIANS(Candidates!$B$9))*COS(RADIANS(Candidates!$B$9))*SIN(RADIANS(Candidates!$C$9-Candidates!$C$9)/2)^2)) -> 0 | G20: =2*6371*ASIN(SQRT(SIN(RADIANS(Candidates!$B$10-Candidates!$B$9)/2)^2+COS(RADIANS(Candidates!$B$9))*COS(RADIANS(Candidates!$B$10))*SIN(RADIANS(Candidates!$C$10-Candidates!$C$9)/2)^2)) -> 22.272954 | H20: =2*6371*ASIN(SQRT(SIN(RADIANS(Candidates!$B$11-Candidates!$B$9)/2)^2+COS(RADIANS(Candidates!$B$9))*COS(RADIANS(Candidates!$B$11))*SIN(RADIANS(Candidates!$C$11-Candidates!$C$9)/2)^2)) -> 17.080011 | I20: =2*6371*ASIN(SQRT(SIN(RADIANS(Candidates!$B$12-Candidates!$B$9)/2)^2+COS(RADIANS(Candidates!$B$9))*COS(RADIANS(Candidates!$B$12))*SIN(RADIANS(Candidates!$C$12-Candidates!$C$9)/2)^2)) -> 7.216949
A21: =Candidates!A10 -> Electronic City | B21: =2*6371*ASIN(SQRT(SIN(RADIANS(Candidates!$B$5-Candidates!$B$10)/2)^2+COS(RADIANS(Candidates!$B$10))*COS(RADIANS(Candidates!$B$5))*SIN(RADIANS(Candidates!$C$5-Candidates!$C$10)/2)^2)) -> 16.931895 | C21: =2*6371*ASIN(SQRT(SIN(RADIANS(Candidates!$B$6-Candidates!$B$10)/2)^2+COS(RADIANS(Candidates!$B$10))*COS(RADIANS(Candidates!$B$6))*SIN(RADIANS(Candidates!$C$6-Candidates!$C$10)/2)^2)) -> 13.187883 | D21: =2*6371*ASIN(SQRT(SIN(RADIANS(Candidates!$B$7-Candidates!$B$10)/2)^2+COS(RADIANS(Candidates!$B$10))*COS(RADIANS(Candidates!$B$7))*SIN(RADIANS(Candidates!$C$7-Candidates!$C$10)/2)^2)) -> 9.1504093 | E21: =2*6371*ASIN(SQRT(SIN(RADIANS(Candidates!$B$8-Candidates!$B$10)/2)^2+COS(RADIANS(Candidates!$B$10))*COS(RADIANS(Candidates!$B$8))*SIN(RADIANS(Candidates!$C$8-Candidates!$C$10)/2)^2)) -> 8.0567771 | F21: =2*6371*ASIN(SQRT(SIN(RADIANS(Candidates!$B$9-Candidates!$B$10)/2)^2+COS(RADIANS(Candidates!$B$10))*COS(RADIANS(Candidates!$B$9))*SIN(RADIANS(Candidates!$C$9-Candidates!$C$10)/2)^2)) -> 22.272954 | G21: =2*6371*ASIN(SQRT(SIN(RADIANS(Candidates!$B$10-Candidates!$B$10)/2)^2+COS(RADIANS(Candidates!$B$10))*COS(RADIANS(Candidates!$B$10))*SIN(RADIANS(Candidates!$C$10-Candidates!$C$10)/2)^2)) -> 0 | H21: =2*6371*ASIN(SQRT(SIN(RADIANS(Candidates!$B$11-Candidates!$B$10)/2)^2+COS(RADIANS(Candidates!$B$10))*COS(RADIANS(Candidates!$B$11))*SIN(RADIANS(Candidates!$C$11-Candidates!$C$10)/2)^2)) -> 11.354838 | I21: =2*6371*ASIN(SQRT(SIN(RADIANS(Candidates!$B$12-Candidates!$B$10)/2)^2+COS(RADIANS(Candidates!$B$10))*COS(RADIANS(Candidates!$B$12))*SIN(RADIANS(Candidates!$C$12-Candidates!$C$10)/2)^2)) -> 29.241871
A22: =Candidates!A11 -> Kanakapura Road | B22: =2*6371*ASIN(SQRT(SIN(RADIANS(Candidates!$B$5-Candidates!$B$11)/2)^2+COS(RADIANS(Candidates!$B$11))*COS(RADIANS(Candidates!$B$5))*SIN(RADIANS(Candidates!$C$5-Candidates!$C$11)/2)^2)) -> 22.226211 | C22: =2*6371*ASIN(SQRT(SIN(RADIANS(Candidates!$B$6-Candidates!$B$11)/2)^2+COS(RADIANS(Candidates!$B$11))*COS(RADIANS(Candidates!$B$6))*SIN(RADIANS(Candidates!$C$6-Candidates!$C$11)/2)^2)) -> 16.841622 | D22: =2*6371*ASIN(SQRT(SIN(RADIANS(Candidates!$B$7-Candidates!$B$11)/2)^2+COS(RADIANS(Candidates!$B$11))*COS(RADIANS(Candidates!$B$7))*SIN(RADIANS(Candidates!$C$7-Candidates!$C$11)/2)^2)) -> 12.964112 | E22: =2*6371*ASIN(SQRT(SIN(RADIANS(Candidates!$B$8-Candidates!$B$11)/2)^2+COS(RADIANS(Candidates!$B$11))*COS(RADIANS(Candidates!$B$8))*SIN(RADIANS(Candidates!$C$8-Candidates!$C$11)/2)^2)) -> 14.824885 | F22: =2*6371*ASIN(SQRT(SIN(RADIANS(Candidates!$B$9-Candidates!$B$11)/2)^2+COS(RADIANS(Candidates!$B$11))*COS(RADIANS(Candidates!$B$9))*SIN(RADIANS(Candidates!$C$9-Candidates!$C$11)/2)^2)) -> 17.080011 | G22: =2*6371*ASIN(SQRT(SIN(RADIANS(Candidates!$B$10-Candidates!$B$11)/2)^2+COS(RADIANS(Candidates!$B$11))*COS(RADIANS(Candidates!$B$10))*SIN(RADIANS(Candidates!$C$10-Candidates!$C$11)/2)^2)) -> 11.354838 | H22: =2*6371*ASIN(SQRT(SIN(RADIANS(Candidates!$B$11-Candidates!$B$11)/2)^2+COS(RADIANS(Candidates!$B$11))*COS(RADIANS(Candidates!$B$11))*SIN(RADIANS(Candidates!$C$11-Candidates!$C$11)/2)^2)) -> 0 | I22: =2*6371*ASIN(SQRT(SIN(RADIANS(Candidates!$B$12-Candidates!$B$11)/2)^2+COS(RADIANS(Candidates!$B$11))*COS(RADIANS(Candidates!$B$12))*SIN(RADIANS(Candidates!$C$12-Candidates!$C$11)/2)^2)) -> 24.172703
A23: =Candidates!A12 -> Yelahanka | B23: =2*6371*ASIN(SQRT(SIN(RADIANS(Candidates!$B$5-Candidates!$B$12)/2)^2+COS(RADIANS(Candidates!$B$12))*COS(RADIANS(Candidates!$B$5))*SIN(RADIANS(Candidates!$C$5-Candidates!$C$12)/2)^2)) -> 22.115405 | C23: =2*6371*ASIN(SQRT(SIN(RADIANS(Candidates!$B$6-Candidates!$B$12)/2)^2+COS(RADIANS(Candidates!$B$12))*COS(RADIANS(Candidates!$B$6))*SIN(RADIANS(Candidates!$C$6-Candidates!$C$12)/2)^2)) -> 19.610472 | D23: =2*6371*ASIN(SQRT(SIN(RADIANS(Candidates!$B$7-Candidates!$B$12)/2)^2+COS(RADIANS(Candidates!$B$12))*COS(RADIANS(Candidates!$B$7))*SIN(RADIANS(Candidates!$C$7-Candidates!$C$12)/2)^2)) -> 21.267143 | E23: =2*6371*ASIN(SQRT(SIN(RADIANS(Candidates!$B$8-Candidates!$B$12)/2)^2+COS(RADIANS(Candidates!$B$12))*COS(RADIANS(Candidates!$B$8))*SIN(RADIANS(Candidates!$C$8-Candidates!$C$12)/2)^2)) -> 24.242772 | F23: =2*6371*ASIN(SQRT(SIN(RADIANS(Candidates!$B$9-Candidates!$B$12)/2)^2+COS(RADIANS(Candidates!$B$12))*COS(RADIANS(Candidates!$B$9))*SIN(RADIANS(Candidates!$C$9-Candidates!$C$12)/2)^2)) -> 7.216949 | G23: =2*6371*ASIN(SQRT(SIN(RADIANS(Candidates!$B$10-Candidates!$B$12)/2)^2+COS(RADIANS(Candidates!$B$12))*COS(RADIANS(Candidates!$B$10))*SIN(RADIANS(Candidates!$C$10-Candidates!$C$12)/2)^2)) -> 29.241871 | H23: =2*6371*ASIN(SQRT(SIN(RADIANS(Candidates!$B$11-Candidates!$B$12)/2)^2+COS(RADIANS(Candidates!$B$12))*COS(RADIANS(Candidates!$B$11))*SIN(RADIANS(Candidates!$C$11-Candidates!$C$12)/2)^2)) -> 24.172703 | I23: =2*6371*ASIN(SQRT(SIN(RADIANS(Candidates!$B$12-Candidates!$B$12)/2)^2+COS(RADIANS(Candidates!$B$12))*COS(RADIANS(Candidates!$B$12))*SIN(RADIANS(Candidates!$C$12-Candidates!$C$12)/2)^2)) -> 0

Sheet Model
A1: Model: demand, cannibalisation and store P&L (mature year, Rs Cr)
A2: All formulas. Change inputs on Candidates / Assumptions.
A4: Location | B4: Households | C4: Grocery wallet / HH / month (Rs) | D4: Organised share | E4: Access factor | F4: Our fair share | G4: Wallet method sales | H4: Avg bill (Rs) | I4: Bills per day | J4: Footfall method sales | K4: Estimate divergence | L4: Gross sales (calibrated) | M4: Sales per sq ft (Rs) | N4: Nearest existing store | O4: Distance (km) | P4: Cannibalisation % | Q4: Net incremental sales | R4: Rent (Rs Cr/yr) | S4: Rent % of sales | T4: Store EBITDA | U4: Contribution lost at existing store | V4: Incremental EBITDA to chain | W4: Capex incl. deposit + inventory | X4: Payback (yrs) | Y4: 9-yr NPV | Z4: Passes financial gate?
A5: =Candidates!A5 -> Whitefield | B5: =Candidates!D5/Assumptions!$B$4 -> 27631.579 | C5: =Candidates!E5*Assumptions!$B$5 -> 17500 | D5: =MIN(Assumptions!$B$8,Assumptions!$B$6+Assumptions!$B$7*Candidates!E5/1000) -> 0.35 | E5: =Candidates!J5/Assumptions!$B$10 -> 1.1428571 | F5: =E5/(E5+Candidates!H5+Assumptions!$B$9) -> 0.11851852 | G5: =B5*C5*D5*F5*12/10^7 -> 24.070175 | H5: =Assumptions!$B$14+Assumptions!$B$15*Candidates!E5/1000 -> 662.5 | I5: =(Candidates!F5*Candidates!G5*Assumptions!$B$11+Candidates!F5*(1-Candidates!G5)*Assumptions!$B$12)*Assumptions!$B$13 -> 990 | J5: =I5*H5*Assumptions!$B$17/10^7 -> 23.939438 | K5: =ABS(G5-J5)/MAX(G5,J5) -> 0.0054315324 | L5: =(Assumptions!$B$16*G5+(1-Assumptions!$B$16)*J5)*Existing_Stores!$C$13 -> 30.600845 | M5: =L5*10^7/Assumptions!$B$18 -> 30600.845 | N5: =Distances!H5 -> Indiranagar | O5: =Distances!I5 -> 11.871087 | P5: =MAX(0,Assumptions!$B$32*(1-O5/Assumptions!$B$33)) -> 0 | Q5: =L5*(1-P5) -> 30.600845 | R5: =Candidates!I5*Assumptions!$B$18*12/10^7 -> 1.74 | S5: =R5/L5 -> 0.056861175 | T5: =L5*Assumptions!$B$19-R5-(Assumptions!$B$20+Assumptions!$B$21)/10^7-L5*Assumptions!$B$22 -> 1.4561352 | U5: =L5*P5*(Assumptions!$B$19-Assumptions!$B$22) -> 0 | V5: =T5-U5 -> 1.4561352 | W5: =(Assumptions!$B$23*Assumptions!$B$18+Assumptions!$B$24*Candidates!I5*Assumptions!$B$18+Assumptions!$B$25)/10^7 -> 3.87 | X5: =IF(V5>0,W5/V5,99) -> 2.6577203 | Y5: =Cashflows!L5 -> 2.6849909 | Z5: =IF(AND(X5<=Assumptions!$B$35,Y5>0),"Yes","No") -> Yes
A6: =Candidates!A6 -> Marathahalli | B6: =Candidates!D6/Assumptions!$B$4 -> 27631.579 | C6: =Candidates!E6*Assumptions!$B$5 -> 13300 | D6: =MIN(Assumptions!$B$8,Assumptions!$B$6+Assumptions!$B$7*Candidates!E6/1000) -> 0.29 | E6: =Candidates!J6/Assumptions!$B$10 -> 0.85714286 | F6: =E6/(E6+Candidates!H6+Assumptions!$B$9) -> 0.091603053 | G6: =B6*C6*D6*F6*12/10^7 -> 11.715115 | H6: =Assumptions!$B$14+Assumptions!$B$15*Candidates!E6/1000 -> 587.5 | I6: =(Candidates!F6*Candidates!G6*Assumptions!$B$11+Candidates!F6*(1-Candidates!G6)*Assumptions!$B$12)*Assumptions!$B$13 -> 1080 | J6: =I6*H6*Assumptions!$B$17/10^7 -> 23.15925 | K6: =ABS(G6-J6)/MAX(G6,J6) -> 0.49414966 | L6: =(Assumptions!$B$16*G6+(1-Assumptions!$B$16)*J6)*Existing_Stores!$C$13 -> 22.228569 | M6: =L6*10^7/Assumptions!$B$18 -> 22228.569 | N6: =Distances!H6 -> Indiranagar | O6: =Distances!I6 -> 6.9576771 | P6: =MAX(0,Assumptions!$B$32*(1-O6/Assumptions!$B$33)) -> 0.045601625 | Q6: =L6*(1-P6) -> 21.214911 | R6: =Candidates!I6*Assumptions!$B$18*12/10^7 -> 1.8 | S6: =R6/L6 -> 0.080976871 | T6: =L6*Assumptions!$B$19-R6-(Assumptions!$B$20+Assumptions!$B$21)/10^7-L6*Assumptions!$B$22 -> 0.056571104 | U6: =L6*P6*(Assumptions!$B$19-Assumptions!$B$22) -> 0.16218542 | V6: =T6-U6 -> -0.10561432 | W6: =(Assumptions!$B$23*Assumptions!$B$18+Assumptions!$B$24*Candidates!I6*Assumptions!$B$18+Assumptions!$B$25)/10^7 -> 3.9 | X6: =IF(V6>0,W6/V6,99) -> 99 | Y6: =Cashflows!L6 -> -7.1823773 | Z6: =IF(AND(X6<=Assumptions!$B$35,Y6>0),"Yes","No") -> No
A7: =Candidates!A7 -> Bellandur | B7: =Candidates!D7/Assumptions!$B$4 -> 28947.368 | C7: =Candidates!E7*Assumptions!$B$5 -> 18900 | D7: =MIN(Assumptions!$B$8,Assumptions!$B$6+Assumptions!$B$7*Candidates!E7/1000) -> 0.37 | E7: =Candidates!J7/Assumptions!$B$10 -> 0.57142857 | F7: =E7/(E7+Candidates!H7+Assumptions!$B$9) -> 0.080808081 | G7: =B7*C7*D7*F7*12/10^7 -> 19.629474 | H7: =Assumptions!$B$14+Assumptions!$B$15*Candidates!E7/1000 -> 687.5 | I7: =(Candidates!F7*Candidates!G7*Assumptions!$B$11+Candidates!F7*(1-Candidates!G7)*Assumptions!$B$12)*Assumptions!$B$13 -> 900 | J7: =I7*H7*Assumptions!$B$17/10^7 -> 22.584375 | K7: =ABS(G7-J7)/MAX(G7,J7) -> 0.1308383 | L7: =(Assumptions!$B$16*G7+(1-Assumptions!$B$16)*J7)*Existing_Stores!$C$13 -> 26.906683 | M7: =L7*10^7/Assumptions!$B$18 -> 26906.683 | N7: =Distances!H7 -> HSR Layout | O7: =Distances!I7 -> 3.5080927 | P7: =MAX(0,Assumptions!$B$32*(1-O7/Assumptions!$B$33)) -> 0.19652094 | Q7: =L7*(1-P7) -> 21.618956 | R7: =Candidates!I7*Assumptions!$B$18*12/10^7 -> 1.56 | S7: =R7/L7 -> 0.057978161 | T7: =L7*Assumptions!$B$19-R7-(Assumptions!$B$20+Assumptions!$B$21)/10^7-L7*Assumptions!$B$22 -> 1.0450693 | U7: =L7*P7*(Assumptions!$B$19-Assumptions!$B$22) -> 0.84603627 | V7: =T7-U7 -> 0.19903298 | W7: =(Assumptions!$B$23*Assumptions!$B$18+Assumptions!$B$24*Candidates!I7*Assumptions!$B$18+Assumptions!$B$25)/10^7 -> 3.78 | X7: =IF(V7>0,W7/V7,99) -> 18.991827 | Y7: =Cashflows!L7 -> -4.1151219 | Z7: =IF(AND(X7<=Assumptions!$B$35,Y7>0),"Yes","No") -> No
